Workbook

Sheet Data
A1: Company | B1: Website | C1: Corporate Form (Official) | D1: Founded Year | E1: Offices (count) | F1: Employees (range) | G1: Design Headcount Ratio (0-1) | H1: Engineering Headcount Ratio (0-1) | I1: Delivery Model | J1: Avg Project Ticket (band) | K1: ISO/IEC 27001 (Y/N) | L1: ISO 9001 (Y/N) | M1: Accessibility Program | N1: Privacy/AI Ethics Policy (public Y/N) | O1: Open Roles (Design) | P1: Open Roles (Data/ML/AI) | Q1: Hiring Velocity (30d) | R1: AI Adoption Index (0–5) | S1: GenAI in Design Ops | T1: AI Roles Present (count) | U1: Model/Stack Disclosure | V1: Patents last 3y (count) | W1: OSS Contributions | X1: Blog Cadence | Y1: Design System Maturity | Z1: Analytics/Experimentation | AA1: Security Review in SDLC | AB1: AI_Adoption_Pts (0-30) | AC1: ISO27001_Pts (0/8) | AD1: Accessibility_Pts (0-6) | AE1: SecSDLC_Pts (0-6) | AF1: Analytics_Pts (0-5) | AG1: Talent_AI_Roles_Pts (0-8) | AH1: HiringVelocity_Pts (0-7) | AI1: Delivery_DesignRatio_Pts (0-8) | AJ1: Delivery_Model_Pts (0-7) | AK1: RnD_OSS_Pts (0-6) | AL1: RnD_Blog_Pts (0-4) | AM1: RnD_Patent_Pts (0-5) | AN1: AI_Adoption_Subtotal (30) | AO1: Ops_Quality_Subtotal (25) | AP1: Talent_Subtotal (15) | AQ1: Delivery_Subtotal (15) | AR1: R&D_Subtotal (15) | AS1: TOTAL_SCORE (0-100) | AT1: Evidence_URL_AI_Adoption | AU1: Evidence_URL_ISO/Certs | AV1: Evidence_URL_Accessibility | AW1: Evidence_URL_SecSDLC | AX1: Evidence_URL_Analytics/Experimentation | AY1: Evidence_URL_Hiring | AZ1: Evidence_URL_ModelStack | BA1: Evidence_URL_OSS | BB1: Evidence_URL_Blog | BC1: Evidence_URL_DesignSystem | BD1: Evidence_Notes
A2: Accenture Song | B2: https://www.accenture.com/ | C2: Business unit of public company | D2: 1989 | E2: 200 | F2: >20k | G2: 0.35 | H2: 0.25 | I2: Distributed nearshore/offshore | J2: >$5M | K2: Y | L2: Y | M2: WCAG AA | N2: Y | O2: 80 | P2: 120 | Q2: High (10+) | R2: 4 | S2: E2E prototyping | T2: 5 | U2: Commercial + in-house RAG | V2: 120 | W2: Contributor | X2: Monthly+ | Y2: Tokens/Multi-brand | Z2: Continuous experimentation | AA2: DevSecOps integrated | AB2: =VALUE(R2)*6 -> 0 | AC2: =IFERROR(VLOOKUP(K2,PointsMap!D2:E3,2,0),0) -> 0 | AD2: =IFERROR(VLOOKUP(M2,PointsMap!G2:H5,2,0),0) -> 0 | AE2: =IFERROR(VLOOKUP(AA2,PointsMap!M2:N5,2,0),0) -> 0 | AF2: =IFERROR(VLOOKUP(Z2,PointsMap!J2:K5,2,0),0) -> 0 | AG2: =MIN(8,VALUE(T2)*2) -> 0 | AH2: =IFERROR(VLOOKUP(Q2,PointsMap!P2:Q5,2,0),0) -> 0 | AI2: =MIN(8,ROUND(VALUE(G2)*8,0)) -> 0 | AJ2: =IFERROR(VLOOKUP(I2,PointsMap!A2:B5,2,0),0) -> 0 | AK2: =IFERROR(VLOOKUP(W2,PointsMap!S2:T4,2,0),0) -> 0 | AL2: =IFERROR(VLOOKUP(X2,PointsMap!V2:W4,2,0),0) -> 0 | AM2: =MIN(5,VALUE(V2)) -> 0 | AN2: =AB2 -> 0 | AO2: =AC2+AD2+AE2+AF2 -> 0 | AP2: =AG2+AH2 -> 0 | AQ2: =AI2+AJ2 -> 0 | AR2: =AK2+AL2+AM2 -> 0 | AS2: =AN2*Weights!B3/100+AO2*Weights!B4/100+AP2*Weights!B5/100+AQ2*Weights!B6/100+AR2*Weights!B7/100 -> 0
A3: Deloitte Digital | B3: https://www.deloittedigital.com/ | C3: Multinational network of independent member firms | D3: 1845 | E3: 150 | F3: >20k | G3: 0.3 | H3: 0.3 | I3: Hybrid | J3: >$5M | K3: Y | L3: Y | M3: WCAG AA | N3: Y | O3: 60 | P3: 90 | Q3: High (10+) | R3: 4 | S3: Component generation | T3: 4 | U3: Commercial LLM | V3: 90 | W3: Contributor | X3: Monthly+ | Y3: Tokens/Multi-brand | Z3: A/B testing | AA3: SAST+DAST | AB3: =VALUE(R3)*6 -> 0 | AC3: =IFERROR(VLOOKUP(K3,PointsMap!D2:E3,2,0),0) -> 0 | AD3: =IFERROR(VLOOKUP(M3,PointsMap!G2:H5,2,0),0) -> 0 | AE3: =IFERROR(VLOOKUP(AA3,PointsMap!M2:N5,2,0),0) -> 0 | AF3: =IFERROR(VLOOKUP(Z3,PointsMap!J2:K5,2,0),0) -> 0 | AG3: =MIN(8,VALUE(T3)*2) -> 0 | AH3: =IFERROR(VLOOKUP(Q3,PointsMap!P2:Q5,2,0),0) -> 0 | AI3: =MIN(8,ROUND(VALUE(G3)*8,0)) -> 0 | AJ3: =IFERROR(VLOOKUP(I3,PointsMap!A2:B5,2,0),0) -> 0 | AK3: =IFERROR(VLOOKUP(W3,PointsMap!S2:T4,2,0),0) -> 0 | AL3: =IFERROR(VLOOKUP(X3,PointsMap!V2:W4,2,0),0) -> 0 | AM3: =MIN(5,VALUE(V3)) -> 0 | AN3: =AB3 -> 0 | AO3: =AC3+AD3+AE3+AF3 -> 0 | AP3: =AG3+AH3 -> 0 | AQ3: =AI3+AJ3 -> 0 | AR3: =AK3+AL3+AM3 -> 0 | AS3: =AN3*Weights!B3/100+AO3*Weights!B4/100+AP3*Weights!B5/100+AQ3*Weights!B6/100+AR3*Weights!B7/100 -> 0 | AT3: https://www.deloitte.com/us/en/what-we-do/capabilities/applied-artificial-intelligence/services/ethics-of-ai-framework.html | AV3: https://www.deloitte.com/global/en/legal/accessibility-statement.html | AY3: https://apply.deloitte.com/ | AZ3: https://www.deloitte.com/us/en/what-we-do/capabilities/applied-artificial-intelligence/articles/trustworthy-ai-governance-in-practice.html | BA3: https://github.com/DeloitteDigital | BB3: https://www2.deloitte.com/us/en/insights.html | BD3: Trustworthy AI framework; global accessibility statement; OSS org placeholder (no public repos).
A4: IBM iX | B4: https://www.ibm.com/consulting/ibmix | C4: Business unit of public company | D4: 1911 | E4: 80 | F4: >20k | G4: 0.25 | H4: 0.45 | I4: Hybrid | J4: >$5M | K4: Y | L4: Y | M4: WCAG AA | N4: Y | O4: 40 | P4: 150 | Q4: High (10+) | R4: 4 | S4: E2E prototyping | T4: 5 | U4: Proprietary model / Hybrid | V4: 500 | W4: Maintainer | X4: Monthly+ | Y4: CI/CD integrated | Z4: Continuous experimentation | AA4: DevSecOps integrated | AB4: =VALUE(R4)*6 -> 0 | AC4: =IFERROR(VLOOKUP(K4,PointsMap!D2:E3,2,0),0) -> 0 | AD4: =IFERROR(VLOOKUP(M4,PointsMap!G2:H5,2,0),0) -> 0 | AE4: =IFERROR(VLOOKUP(AA4,PointsMap!M2:N5,2,0),0) -> 0 | AF4: =IFERROR(VLOOKUP(Z4,PointsMap!J2:K5,2,0),0) -> 0 | AG4: =MIN(8,VALUE(T4)*2) -> 0 | AH4: =IFERROR(VLOOKUP(Q4,PointsMap!P2:Q5,2,0),0) -> 0 | AI4: =MIN(8,ROUND(VALUE(G4)*8,0)) -> 0 | AJ4: =IFERROR(VLOOKUP(I4,PointsMap!A2:B5,2,0),0) -> 0 | AK4: =IFERROR(VLOOKUP(W4,PointsMap!S2:T4,2,0),0) -> 0 | AL4: =IFERROR(VLOOKUP(X4,PointsMap!V2:W4,2,0),0) -> 0 | AM4: =MIN(5,VALUE(V4)) -> 0 | AN4: =AB4 -> 0 | AO4: =AC4+AD4+AE4+AF4 -> 0 | AP4: =AG4+AH4 -> 0 | AQ4: =AI4+AJ4 -> 0 | AR4: =AK4+AL4+AM4 -> 0 | AS4: =AN4*Weights!B3/100+AO4*Weights!B4/100+AP4*Weights!B5/100+AQ4*Weights!B6/100+AR4*Weights!B7/100 -> 0 | AT4: https://ibmix.de/en/services/ai-data-transformation | AW4: https://www.ibm.com/support/pages/ibm-global-business-unit-iso-27001-certifications | AY4: https://www.ibm.com/careers | AZ4: https://www.ibm.com/trust/responsible-ai | BA4: https://github.com/ibm | BB4: https://www.ibm.com/blog | BC4: https://www.ibm.com/design/language/ | BD4: IBM Responsible AI principles; ISO 27001 certifications by unit; IBM Design Language reference.
A5: Publicis Sapient | B5: https://www.publicissapient.com/ | C5: Subsidiary brand of public holding company | D5: 1990 | E5: 50 | F5: 5k–20k | G5: 0.4 | H5: 0.35 | I5: Distributed nearshore/offshore | J5: $1M–$5M | K5: Y | L5: Y | M5: WCAG AA | N5: Y | O5: 35 | P5: 70 | Q5: Mid (4–9) | R5: 3 | S5: Component generation | T5: 4 | U5: Commercial + in-house RAG | V5: 60 | W5: Contributor | X5: Monthly+ | Y5: Tokens/Multi-brand | Z5: A/B testing | AA5: SAST+DAST | AB5: =VALUE(R5)*6 -> 0 | AC5: =IFERROR(VLOOKUP(K5,PointsMap!D2:E3,2,0),0) -> 0 | AD5: =IFERROR(VLOOKUP(M5,PointsMap!G2:H5,2,0),0) -> 0 | AE5: =IFERROR(VLOOKUP(AA5,PointsMap!M2:N5,2,0),0) -> 0 | AF5: =IFERROR(VLOOKUP(Z5,PointsMap!J2:K5,2,0),0) -> 0 | AG5: =MIN(8,VALUE(T5)*2) -> 0 | AH5: =IFERROR(VLOOKUP(Q5,PointsMap!P2:Q5,2,0),0) -> 0 | AI5: =MIN(8,ROUND(VALUE(G5)*8,0)) -> 0 | AJ5: =IFERROR(VLOOKUP(I5,PointsMap!A2:B5,2,0),0) -> 0 | AK5: =IFERROR(VLOOKUP(W5,PointsMap!S2:T4,2,0),0) -> 0 | AL5: =IFERROR(VLOOKUP(X5,PointsMap!V2:W4,2,0),0) -> 0 | AM5: =MIN(5,VALUE(V5)) -> 0 | AN5: =AB5 -> 0 | AO5: =AC5+AD5+AE5+AF5 -> 0 | AP5: =AG5+AH5 -> 0 | AQ5: =AI5+AJ5 -> 0 | AR5: =AK5+AL5+AM5 -> 0 | AS5: =AN5*Weights!B3/100+AO5*Weights!B4/100+AP5*Weights!B5/100+AQ5*Weights!B6/100+AR5*Weights!B7/100 -> 0 | AT5: https://careers.publicissapient.com/life-at-ps/blog/the-place-for-engineering-and-tech-trailblazers | AW5: https://www.publicissapient.com/ | AY5: https://careers.publicissapient.com/ | AZ5: https://www.fintechstrategy.com/blog/2025/06/02/publicis-sapient-why-ai-in-banking-is-only-as-smart-as-the-systems-behind-it/ | BA5: https://github.com/publicissapient | BB5: https://careers.publicissapient.com/life-at-ps/blog | BD5: PS engineering blog and OSS org; ISO alignment via Publicis Groupe disclosures.
A6: Capgemini Invent / frog | B6: https://www.frog.co/ | C6: Subsidiary brand of public holding company | D6: 1967 | E6: 70 | F6: 5k–20k | G6: 0.45 | H6: 0.25 | I6: Hybrid | J6: $1M–$5M | K6: Y | L6: Y | M6: WCAG AA | N6: Y | O6: 50 | P6: 60 | Q6: Mid (4–9) | R6: 3 | S6: Copy/Localization | T6: 3 | U6: Commercial LLM | V6: 40 | W6: Contributor | X6: Quarterly | Y6: Tokens/Multi-brand | Z6: A/B testing | AA6: Lint/Static analysis | AB6: =VALUE(R6)*6 -> 0 | AC6: =IFERROR(VLOOKUP(K6,PointsMap!D2:E3,2,0),0) -> 0 | AD6: =IFERROR(VLOOKUP(M6,PointsMap!G2:H5,2,0),0) -> 0 | AE6: =IFERROR(VLOOKUP(AA6,PointsMap!M2:N5,2,0),0) -> 0 | AF6: =IFERROR(VLOOKUP(Z6,PointsMap!J2:K5,2,0),0) -> 0 | AG6: =MIN(8,VALUE(T6)*2) -> 0 | AH6: =IFERROR(VLOOKUP(Q6,PointsMap!P2:Q5,2,0),0) -> 0 | AI6: =MIN(8,ROUND(VALUE(G6)*8,0)) -> 0 | AJ6: =IFERROR(VLOOKUP(I6,PointsMap!A2:B5,2,0),0) -> 0 | AK6: =IFERROR(VLOOKUP(W6,PointsMap!S2:T4,2,0),0) -> 0 | AL6: =IFERROR(VLOOKUP(X6,PointsMap!V2:W4,2,0),0) -> 0 | AM6: =MIN(5,VALUE(V6)) -> 0 | AN6: =AB6 -> 0 | AO6: =AC6+AD6+AE6+AF6 -> 0 | AP6: =AG6+AH6 -> 0 | AQ6: =AI6+AJ6 -> 0 | AR6: =AK6+AL6+AM6 -> 0 | AS6: =AN6*Weights!B3/100+AO6*Weights!B4/100+AP6*Weights!B5/100+AQ6*Weights!B6/100+AR6*Weights!B7/100 -> 0 | AT6: https://www.frog.co/capabilities | AY6: https://www.frog.co/careers | BB6: https://www.frog.co/designmind | BD6: Capabilities; DesignMind blog; careers.
A7: AKQA | B7: https://www.akqa.com/ | C7: Subsidiary brand of public holding company | D7: 1994 | E7: 29 | F7: 1–5k | G7: 0.55 | H7: 0.2 | I7: Hybrid | J7: $250k–$1M | K7: N | L7: N | M7: WCAG AA | N7: Y | O7: 25 | P7: 15 | Q7: Low (1–3) | R7: 3 | S7: Asset generation | T7: 3 | U7: Commercial LLM | V7: 10 | W7: Contributor | X7: Monthly+ | Y7: Guidelines | Z7: Event tracking | AA7: Lint/Static analysis | AB7: =VALUE(R7)*6 -> 0 | AC7: =IFERROR(VLOOKUP(K7,PointsMap!D2:E3,2,0),0) -> 0 | AD7: =IFERROR(VLOOKUP(M7,PointsMap!G2:H5,2,0),0) -> 0 | AE7: =IFERROR(VLOOKUP(AA7,PointsMap!M2:N5,2,0),0) -> 0 | AF7: =IFERROR(VLOOKUP(Z7,PointsMap!J2:K5,2,0),0) -> 0 | AG7: =MIN(8,VALUE(T7)*2) -> 0 | AH7: =IFERROR(VLOOKUP(Q7,PointsMap!P2:Q5,2,0),0) -> 0 | AI7: =MIN(8,ROUND(VALUE(G7)*8,0)) -> 0 | AJ7: =IFERROR(VLOOKUP(I7,PointsMap!A2:B5,2,0),0) -> 0 | AK7: =IFERROR(VLOOKUP(W7,PointsMap!S2:T4,2,0),0) -> 0 | AL7: =IFERROR(VLOOKUP(X7,PointsMap!V2:W4,2,0),0) -> 0 | AM7: =MIN(5,VALUE(V7)) -> 0 | AN7: =AB7 -> 0 | AO7: =AC7+AD7+AE7+AF7 -> 0 | AP7: =AG7+AH7 -> 0 | AQ7: =AI7+AJ7 -> 0 | AR7: =AK7+AL7+AM7 -> 0 | AS7: =AN7*Weights!B3/100+AO7*Weights!B4/100+AP7*Weights!B5/100+AQ7*Weights!B6/100+AR7*Weights!B7/100 -> 0 | AT7: https://www.akqa.com/work/here/simply-here/ | AV7: https://www.akqa.com/careers/what-we-look-for/ | AY7: https://www.akqa.com/careers/ | BB7: https://www.akqa.com/work/ | BD7: Case examples and careers; no public ISO page found in quick pass.
A8: R/GA | B8: https://rga.com/ | C8: Subsidiary brand of public holding company | D8: 1977 | E8: 15 | F8: 1–5k | G8: 0.55 | H8: 0.25 | I8: Hybrid | J8: $250k–$1M | K8: N | L8: N | M8: WCAG AA | N8: Y | O8: 20 | P8: 20 | Q8: Low (1–3) | R8: 3 | S8: Asset generation | T8: 3 | U8: Commercial LLM | V8: 8 | W8: Contributor | X8: Monthly+ | Y8: Guidelines | Z8: A/B testing | AA8: Lint/Static analysis | AB8: =VALUE(R8)*6 -> 0 | AC8: =IFERROR(VLOOKUP(K8,PointsMap!D2:E3,2,0),0) -> 0 | AD8: =IFERROR(VLOOKUP(M8,PointsMap!G2:H5,2,0),0) -> 0 | AE8: =IFERROR(VLOOKUP(AA8,PointsMap!M2:N5,2,0),0) -> 0 | AF8: =IFERROR(VLOOKUP(Z8,PointsMap!J2:K5,2,0),0) -> 0 | AG8: =MIN(8,VALUE(T8)*2) -> 0 | AH8: =IFERROR(VLOOKUP(Q8,PointsMap!P2:Q5,2,0),0) -> 0 | AI8: =MIN(8,ROUND(VALUE(G8)*8,0)) -> 0 | AJ8: =IFERROR(VLOOKUP(I8,PointsMap!A2:B5,2,0),0) -> 0 | AK8: =IFERROR(VLOOKUP(W8,PointsMap!S2:T4,2,0),0) -> 0 | AL8: =IFERROR(VLOOKUP(X8,PointsMap!V2:W4,2,0),0) -> 0 | AM8: =MIN(5,VALUE(V8)) -> 0 | AN8: =AB8 -> 0 | AO8: =AC8+AD8+AE8+AF8 -> 0 | AP8: =AG8+AH8 -> 0 | AQ8: =AI8+AJ8 -> 0 | AR8: =AK8+AL8+AM8 -> 0 | AS8: =AN8*Weights!B3/100+AO8*Weights!B4/100+AP8*Weights!B5/100+AQ8*Weights!B6/100+AR8*Weights!B7/100 -> 0 | AT8: https://rga.com/ | AY8: https://rga.com/careers | BB8: https://rga.com/work | BD8: Corporate site + careers.
A9: Huge | B9: https://www.hugeinc.com/ | C9: Subsidiary brand of public holding company | D9: 1999 | E9: 13 | F9: 1–5k | G9: 0.55 | H9: 0.2 | I9: Hybrid | J9: $250k–$1M | K9: N | L9: N | M9: Guidelines only | N9: Y | O9: 15 | P9: 10 | Q9: Low (1–3) | R9: 2 | S9: Copy/Localization | T9: 2 | U9: Commercial LLM | V9: 5 | W9: None | X9: Quarterly | Y9: Guidelines | Z9: Event tracking | AA9: None | AB9: =VALUE(R9)*6 -> 0 | AC9: =IFERROR(VLOOKUP(K9,PointsMap!D2:E3,2,0),0) -> 0 | AD9: =IFERROR(VLOOKUP(M9,PointsMap!G2:H5,2,0),0) -> 0 | AE9: =IFERROR(VLOOKUP(AA9,PointsMap!M2:N5,2,0),0) -> 0 | AF9: =IFERROR(VLOOKUP(Z9,PointsMap!J2:K5,2,0),0) -> 0 | AG9: =MIN(8,VALUE(T9)*2) -> 0 | AH9: =IFERROR(VLOOKUP(Q9,PointsMap!P2:Q5,2,0),0) -> 0 | AI9: =MIN(8,ROUND(VALUE(G9)*8,0)) -> 0 | AJ9: =IFERROR(VLOOKUP(I9,PointsMap!A2:B5,2,0),0) -> 0 | AK9: =IFERROR(VLOOKUP(W9,PointsMap!S2:T4,2,0),0) -> 0 | AL9: =IFERROR(VLOOKUP(X9,PointsMap!V2:W4,2,0),0) -> 0 | AM9: =MIN(5,VALUE(V9)) -> 0 | AN9: =AB9 -> 0 | AO9: =AC9+AD9+AE9+AF9 -> 0 | AP9: =AG9+AH9 -> 0 | AQ9: =AI9+AJ9 -> 0 | AR9: =AK9+AL9+AM9 -> 0 | AS9: =AN9*Weights!B3/100+AO9*Weights!B4/100+AP9*Weights!B5/100+AQ9*Weights!B6/100+AR9*Weights!B7/100 -> 0 | AT9: https://www.hugeinc.com/ | AY9: https://www.hugeinc.com/careers/ | BB9: https://www.hugeinc.com/work/ | BD9: Corporate and careers pages.
A10: IDEO | B10: https://www.ideo.com/ | C10: Private company | D10: 1991 | E10: 10 | F10: 500–1k | G10: 0.65 | H10: 0.15 | I10: Hybrid | J10: $250k–$1M | K10: N | L10: N | M10: WCAG AA | N10: Y | O10: 10 | P10: 5 | Q10: Low (1–3) | R10: 2 | S10: Copy/Localization | T10: 2 | U10: Not disclosed | V10: 12 | W10: Contributor | X10: Monthly+ | Y10: Tokens/Multi-brand | Z10: Event tracking | AA10: Lint/Static analysis | AB10: =VALUE(R10)*6 -> 0 | AC10: =IFERROR(VLOOKUP(K10,PointsMap!D2:E3,2,0),0) -> 0 | AD10: =IFERROR(VLOOKUP(M10,PointsMap!G2:H5,2,0),0) -> 0 | AE10: =IFERROR(VLOOKUP(AA10,PointsMap!M2:N5,2,0),0) -> 0 | AF10: =IFERROR(VLOOKUP(Z10,PointsMap!J2:K5,2,0),0) -> 0 | AG10: =MIN(8,VALUE(T10)*2) -> 0 | AH10: =IFERROR(VLOOKUP(Q10,PointsMap!P2:Q5,2,0),0) -> 0 | AI10: =MIN(8,ROUND(VALUE(G10)*8,0)) -> 0 | AJ10: =IFERROR(VLOOKUP(I10,PointsMap!A2:B5,2,0),0) -> 0 | AK10: =IFERROR(VLOOKUP(W10,PointsMap!S2:T4,2,0),0) -> 0 | AL10: =IFERROR(VLOOKUP(X10,PointsMap!V2:W4,2,0),0) -> 0 | AM10: =MIN(5,VALUE(V10)) -> 0 | AN10: =AB10 -> 0 | AO10: =AC10+AD10+AE10+AF10 -> 0 | AP10: =AG10+AH10 -> 0 | AQ10: =AI10+AJ10 -> 0 | AR10: =AK10+AL10+AM10 -> 0 | AS10: =AN10*Weights!B3/100+AO10*Weights!B4/100+AP10*Weights!B5/100+AQ10*Weights!B6/100+AR10*Weights!B7/100 -> 0 | AT10: https://www.ideo.com/inclusion | AV10: https://www.ideo.com/journal/inside-our-effort-to-make-design-careers-more-accessible | AY10: https://www.ideo.com/careers | BB10: https://www.ideo.com/journal | BD10: Inclusive design program page; careers and journal as evidence of cadence.
A11: Pentagram | B11: https://www.pentagram.com/ | C11: Independent studio (partnership or LLP) | D11: 1972 | E11: 5 | F11: 100–499 | G11: 0.8 | H11: 0.05 | I11: Onsite | J11: $250k–$1M | K11: N | L11: N | M11: Guidelines only | N11: N | O11: 5 | P11: 0 | Q11: None | R11: 1 | S11: Asset generation | T11: 1 | U11: Not disclosed | V11: 0 | W11: None | X11: Quarterly | Y11: Guidelines | Z11: None | AB11: =VALUE(R11)*6 -> 0 | AC11: =IFERROR(VLOOKUP(K11,PointsMap!D2:E3,2,0),0) -> 0 | AD11: =IFERROR(VLOOKUP(M11,PointsMap!G2:H5,2,0),0) -> 0 | AE11: =IFERROR(VLOOKUP(AA11,PointsMap!M2:N5,2,0),0) -> 0 | AF11: =IFERROR(VLOOKUP(Z11,PointsMap!J2:K5,2,0),0) -> 0 | AG11: =MIN(8,VALUE(T11)*2) -> 0 | AH11: =IFERROR(VLOOKUP(Q11,PointsMap!P2:Q5,2,0),0) -> 0 | AI11: =MIN(8,ROUND(VALUE(G11)*8,0)) -> 0 | AJ11: =IFERROR(VLOOKUP(I11,PointsMap!A2:B5,2,0),0) -> 0 | AK11: =IFERROR(VLOOKUP(W11,PointsMap!S2:T4,2,0),0) -> 0 | AL11: =IFERROR(VLOOKUP(X11,PointsMap!V2:W4,2,0),0) -> 0 | AM11: =MIN(5,VALUE(V11)) -> 0 | AN11: =AB11 -> 0 | AO11: =AC11+AD11+AE11+AF11 -> 0 | AP11: =AG11+AH11 -> 0 | AQ11: =AI11+AJ11 -> 0 | AR11: =AK11+AL11+AM11 -> 0 | AS11: =AN11*Weights!B3/100+AO11*Weights!B4/100+AP11*Weights!B5/100+AQ11*Weights!B6/100+AR11*Weights!B7/100 -> 0 | AY11: https://www.pentagram.com/about | BB11: https://www.pentagram.com/work | BD11: Portfolio and studio info; limited formal disclosures publicly.
A12: EPAM | B12: https://www.epam.com/ | C12: Public company | D12: 1993 | E12: 50 | F12: >20k | G12: 0.25 | H12: 0.55 | I12: Distributed nearshore/offshore | J12: $1M–$5M | K12: Y | L12: Y | M12: WCAG AA | N12: Y | O12: 120 | P12: 220 | Q12: High (10+) | R12: 4 | S12: E2E prototyping | T12: 5 | U12: Commercial + in-house RAG | V12: 300 | W12: Maintainer | X12: Monthly+ | Y12: CI/CD integrated | Z12: Continuous experimentation | AA12: DevSecOps integrated | AB12: =VALUE(R12)*6 -> 0 | AC12: =IFERROR(VLOOKUP(K12,PointsMap!D2:E3,2,0),0) -> 0 | AD12: =IFERROR(VLOOKUP(M12,PointsMap!G2:H5,2,0),0) -> 0 | AE12: =IFERROR(VLOOKUP(AA12,PointsMap!M2:N5,2,0),0) -> 0 | AF12: =IFERROR(VLOOKUP(Z12,PointsMap!J2:K5,2,0),0) -> 0 | AG12: =MIN(8,VALUE(T12)*2) -> 0 | AH12: =IFERROR(VLOOKUP(Q12,PointsMap!P2:Q5,2,0),0) -> 0 | AI12: =MIN(8,ROUND(VALUE(G12)*8,0)) -> 0 | AJ12: =IFERROR(VLOOKUP(I12,PointsMap!A2:B5,2,0),0) -> 0 | AK12: =IFERROR(VLOOKUP(W12,PointsMap!S2:T4,2,0),0) -> 0 | AL12: =IFERROR(VLOOKUP(X12,PointsMap!V2:W4,2,0),0) -> 0 | AM12: =MIN(5,VALUE(V12)) -> 0 | AN12: =AB12 -> 0 | AO12: =AC12+AD12+AE12+AF12 -> 0 | AP12: =AG12+AH12 -> 0 | AQ12: =AI12+AJ12 -> 0 | AR12: =AK12+AL12+AM12 -> 0 | AS12: =AN12*Weights!B3/100+AO12*Weights!B4/100+AP12*Weights!B5/100+AQ12*Weights!B6/100+AR12*Weights!B7/100 -> 0 | AT12: https://www.epam.com/services/artificial-intelligence | AW12: https://www.epam.com/about/social-responsibility/information-security | AY12: https://www.epam.com/careers | BA12: https://github.com/epam | BB12: https://www.epam.com/insights | BD12: AI services page; compliance and security pages; OSS org.
A13: Globant | B13: https://www.globant.com/ | C13: Public company | D13: 2003 | E13: 40 | F13: >20k | G13: 0.3 | H13: 0.5 | I13: Distributed nearshore/offshore | J13: $1M–$5M | K13: Y | L13: Y | M13: WCAG AA | N13: Y | O13: 90 | P13: 180 | Q13: High (10+) | R13: 4 | S13: Component generation | T13: 4 | U13: Commercial + in-house RAG | V13: 150 | W13: Maintainer | X13: Monthly+ | Y13: Tokens/Multi-brand | Z13: A/B testing | AA13: SAST+DAST | AB13: =VALUE(R13)*6 -> 0 | AC13: =IFERROR(VLOOKUP(K13,PointsMap!D2:E3,2,0),0) -> 0 | AD13: =IFERROR(VLOOKUP(M13,PointsMap!G2:H5,2,0),0) -> 0 | AE13: =IFERROR(VLOOKUP(AA13,PointsMap!M2:N5,2,0),0) -> 0 | AF13: =IFERROR(VLOOKUP(Z13,PointsMap!J2:K5,2,0),0) -> 0 | AG13: =MIN(8,VALUE(T13)*2) -> 0 | AH13: =IFERROR(VLOOKUP(Q13,PointsMap!P2:Q5,2,0),0) -> 0 | AI13: =MIN(8,ROUND(VALUE(G13)*8,0)) -> 0 | AJ13: =IFERROR(VLOOKUP(I13,PointsMap!A2:B5,2,0),0) -> 0 | AK13: =IFERROR(VLOOKUP(W13,PointsMap!S2:T4,2,0),0) -> 0 | AL13: =IFERROR(VLOOKUP(X13,PointsMap!V2:W4,2,0),0) -> 0 | AM13: =MIN(5,VALUE(V13)) -> 0 | AN13: =AB13 -> 0 | AO13: =AC13+AD13+AE13+AF13 -> 0 | AP13: =AG13+AH13 -> 0 | AQ13: =AI13+AJ13 -> 0 | AR13: =AK13+AL13+AM13 -> 0 | AS13: =AN13*Weights!B3/100+AO13*Weights!B4/100+AP13*Weights!B5/100+AQ13*Weights!B6/100+AR13*Weights!B7/100 -> 0 | AT13: https://www.globant.com/studio/ai | AW13: https://www.globant.com/sustainability/information-security | AY13: https://www.globant.com/careers | BA13: https://github.com/globant | BB13: https://www.globant.com/insights | BD13: AI studio; InfoSec page; OSS org; insights blog.
A14: Valtech | B14: https://www.valtech.com/ | C14: Private company | D14: 1993 | E14: 20 | F14: 5k–20k | G14: 0.35 | H14: 0.45 | I14: Distributed nearshore/offshore | J14: $1M–$5M | K14: Y | L14: Y | M14: WCAG AA | N14: Y | O14: 40 | P14: 60 | Q14: Mid (4–9) | R14: 3 | S14: Copy/Localization | T14: 3 | U14: Commercial LLM | V14: 25 | W14: Contributor | X14: Monthly+ | Y14: Tokens/Multi-brand | Z14: A/B testing | AA14: SAST+DAST | AB14: =VALUE(R14)*6 -> 0 | AC14: =IFERROR(VLOOKUP(K14,PointsMap!D2:E3,2,0),0) -> 0 | AD14: =IFERROR(VLOOKUP(M14,PointsMap!G2:H5,2,0),0) -> 0 | AE14: =IFERROR(VLOOKUP(AA14,PointsMap!M2:N5,2,0),0) -> 0 | AF14: =IFERROR(VLOOKUP(Z14,PointsMap!J2:K5,2,0),0) -> 0 | AG14: =MIN(8,VALUE(T14)*2) -> 0 | AH14: =IFERROR(VLOOKUP(Q14,PointsMap!P2:Q5,2,0),0) -> 0 | AI14: =MIN(8,ROUND(VALUE(G14)*8,0)) -> 0 | AJ14: =IFERROR(VLOOKUP(I14,PointsMap!A2:B5,2,0),0) -> 0 | AK14: =IFERROR(VLOOKUP(W14,PointsMap!S2:T4,2,0),0) -> 0 | AL14: =IFERROR(VLOOKUP(X14,PointsMap!V2:W4,2,0),0) -> 0 | AM14: =MIN(5,VALUE(V14)) -> 0 | AN14: =AB14 -> 0 | AO14: =AC14+AD14+AE14+AF14 -> 0 | AP14: =AG14+AH14 -> 0 | AQ14: =AI14+AJ14 -> 0 | AR14: =AK14+AL14+AM14 -> 0 | AS14: =AN14*Weights!B3/100+AO14*Weights!B4/100+AP14*Weights!B5/100+AQ14*Weights!B6/100+AR14*Weights!B7/100 -> 0 | AT14: https://www.valtech.com/insights/topic/ai/ | AW14: https://www.valtech.com/about/information-security/ | AY14: https://www.valtech.com/careers/ | BA14: https://github.com/valtech | BB14: https://www.valtech.com/insights/ | BD14: AI insights hub; InfoSec; careers; OSS.
A15: Endava | B15: https://www.endava.com/ | C15: Public company | D15: 2000 | E15: 30 | F15: 5k–20k | G15: 0.3 | H15: 0.55 | I15: Distributed nearshore/offshore | J15: $1M–$5M | K15: Y | L15: Y | M15: WCAG AA | N15: Y | O15: 50 | P15: 100 | Q15: Mid (4–9) | R15: 3 | S15: Component generation | T15: 3 | U15: Commercial LLM | V15: 60 | W15: Contributor | X15: Quarterly | Y15: Tokens/Multi-brand | Z15: A/B testing | AA15: SAST+DAST | AB15: =VALUE(R15)*6 -> 0 | AC15: =IFERROR(VLOOKUP(K15,PointsMap!D2:E3,2,0),0) -> 0 | AD15: =IFERROR(VLOOKUP(M15,PointsMap!G2:H5,2,0),0) -> 0 | AE15: =IFERROR(VLOOKUP(AA15,PointsMap!M2:N5,2,0),0) -> 0 | AF15: =IFERROR(VLOOKUP(Z15,PointsMap!J2:K5,2,0),0) -> 0 | AG15: =MIN(8,VALUE(T15)*2) -> 0 | AH15: =IFERROR(VLOOKUP(Q15,PointsMap!P2:Q5,2,0),0) -> 0 | AI15: =MIN(8,ROUND(VALUE(G15)*8,0)) -> 0 | AJ15: =IFERROR(VLOOKUP(I15,PointsMap!A2:B5,2,0),0) -> 0 | AK15: =IFERROR(VLOOKUP(W15,PointsMap!S2:T4,2,0),0) -> 0 | AL15: =IFERROR(VLOOKUP(X15,PointsMap!V2:W4,2,0),0) -> 0 | AM15: =MIN(5,VALUE(V15)) -> 0 | AN15: =AB15 -> 0 | AO15: =AC15+AD15+AE15+AF15 -> 0 | AP15: =AG15+AH15 -> 0 | AQ15: =AI15+AJ15 -> 0 | AR15: =AK15+AL15+AM15 -> 0 | AS15: =AN15*Weights!B3/100+AO15*Weights!B4/100+AP15*Weights!B5/100+AQ15*Weights!B6/100+AR15*Weights!B7/100 -> 0 | AT15: https://www.endava.com/capabilities/ai-automation | AW15: https://www.endava.com/about/security | AY15: https://www.endava.com/careers | BA15: https://github.com/endava | BB15: https://www.endava.com/insights | BD15: AI & Automation capability; security page; sustainability/governance mentions ISO certs.
A16: CI&T | B16: https://www.ciandt.com/ | C16: Public company | D16: 1995 | E16: 25 | F16: 5k–20k | G16: 0.35 | H16: 0.45 | I16: Distributed nearshore/offshore | J16: $1M–$5M | K16: Y | L16: Y | M16: WCAG AA | N16: Y | O16: 35 | P16: 70 | Q16: Mid (4–9) | R16: 3 | S16: Copy/Localization | T16: 3 | U16: Commercial LLM | V16: 40 | W16: Contributor | X16: Monthly+ | Y16: Tokens/Multi-brand | Z16: A/B testing | AA16: Lint/Static analysis | AB16: =VALUE(R16)*6 -> 0 | AC16: =IFERROR(VLOOKUP(K16,PointsMap!D2:E3,2,0),0) -> 0 | AD16: =IFERROR(VLOOKUP(M16,PointsMap!G2:H5,2,0),0) -> 0 | AE16: =IFERROR(VLOOKUP(AA16,PointsMap!M2:N5,2,0),0) -> 0 | AF16: =IFERROR(VLOOKUP(Z16,PointsMap!J2:K5,2,0),0) -> 0 | AG16: =MIN(8,VALUE(T16)*2) -> 0 | AH16: =IFERROR(VLOOKUP(Q16,PointsMap!P2:Q5,2,0),0) -> 0 | AI16: =MIN(8,ROUND(VALUE(G16)*8,0)) -> 0 | AJ16: =IFERROR(VLOOKUP(I16,PointsMap!A2:B5,2,0),0) -> 0 | AK16: =IFERROR(VLOOKUP(W16,PointsMap!S2:T4,2,0),0) -> 0 | AL16: =IFERROR(VLOOKUP(X16,PointsMap!V2:W4,2,0),0) -> 0 | AM16: =MIN(5,VALUE(V16)) -> 0 | AN16: =AB16 -> 0 | AO16: =AC16+AD16+AE16+AF16 -> 0 | AP16: =AG16+AH16 -> 0 | AQ16: =AI16+AJ16 -> 0 | AR16: =AK16+AL16+AM16 -> 0 | AS16: =AN16*Weights!B3/100+AO16*Weights!B4/100+AP16*Weights!B5/100+AQ16*Weights!B6/100+AR16*Weights!B7/100 -> 0 | AT16: https://ciandt.com/us/en-us/ai | AW16: https://ciandt.com/us/en-us/lp/security-and-privacy | AY16: https://ciandt.com/us/en-us/careers | BA16: https://github.com/ciandt | BB16: https://ciandt.com/us/en-us/latest-content | BD16: AI practice page; security/privacy page; OSS.
A17: Thoughtworks | B17: https://www.thoughtworks.com/ | C17: Public company | D17: 1993 | E17: 40 | F17: 5k–20k | G17: 0.4 | H17: 0.45 | I17: Distributed nearshore/offshore | J17: $250k–$1M | K17: Y | L17: Y | M17: WCAG AA | N17: Y | O17: 50 | P17: 90 | Q17: Mid (4–9) | R17: 3 | S17: Component generation | T17: 3 | U17: Commercial + in-house RAG | V17: 80 | W17: Maintainer | X17: Monthly+ | Y17: Tokens/Multi-brand | Z17: Continuous experimentation | AA17: DevSecOps integrated | AB17: =VALUE(R17)*6 -> 0 | AC17: =IFERROR(VLOOKUP(K17,PointsMap!D2:E3,2,0),0) -> 0 | AD17: =IFERROR(VLOOKUP(M17,PointsMap!G2:H5,2,0),0) -> 0 | AE17: =IFERROR(VLOOKUP(AA17,PointsMap!M2:N5,2,0),0) -> 0 | AF17: =IFERROR(VLOOKUP(Z17,PointsMap!J2:K5,2,0),0) -> 0 | AG17: =MIN(8,VALUE(T17)*2) -> 0 | AH17: =IFERROR(VLOOKUP(Q17,PointsMap!P2:Q5,2,0),0) -> 0 | AI17: =MIN(8,ROUND(VALUE(G17)*8,0)) -> 0 | AJ17: =IFERROR(VLOOKUP(I17,PointsMap!A2:B5,2,0),0) -> 0 | AK17: =IFERROR(VLOOKUP(W17,PointsMap!S2:T4,2,0),0) -> 0 | AL17: =IFERROR(VLOOKUP(X17,PointsMap!V2:W4,2,0),0) -> 0 | AM17: =MIN(5,VALUE(V17)) -> 0 | AN17: =AB17 -> 0 | AO17: =AC17+AD17+AE17+AF17 -> 0 | AP17: =AG17+AH17 -> 0 | AQ17: =AI17+AJ17 -> 0 | AR17: =AK17+AL17+AM17 -> 0 | AS17: =AN17*Weights!B3/100+AO17*Weights!B4/100+AP17*Weights!B5/100+AQ17*Weights!B6/100+AR17*Weights!B7/100 -> 0 | AT17: https://www.thoughtworks.com/en-us/what-we-do/artificial-intelligence | AW17: https://www.thoughtworks.com/en-us/what-we-do/secure-by-design | AY17: https://www.thoughtworks.com/en-us/careers | AZ17: https://www.thoughtworks.com/en-us/insights/articles/responsible-tech-playbook | BA17: https://github.com/thoughtworks | BB17: https://www.thoughtworks.com/insights | BD17: Responsible tech & AI practice; secure-by-design; Tech Radar/insights as cadence evidence.
A18: Designit (Wipro) | B18: https://www.designit.com/ | C18: Business unit of public company | D18: 1991 | E18: 18 | F18: 1–5k | G18: 0.6 | H18: 0.2 | I18: Hybrid | J18: $250k–$1M | K18: N | L18: N | M18: WCAG AA | N18: Y | O18: 15 | P18: 12 | Q18: Low (1–3) | R18: 2 | S18: Copy/Localization | T18: 2 | U18: Commercial LLM | V18: 4 | W18: Contributor | X18: Quarterly | Y18: Guidelines | Z18: Event tracking | AA18: Lint/Static analysis | AB18: =VALUE(R18)*6 -> 0 | AC18: =IFERROR(VLOOKUP(K18,PointsMap!D2:E3,2,0),0) -> 0 | AD18: =IFERROR(VLOOKUP(M18,PointsMap!G2:H5,2,0),0) -> 0 | AE18: =IFERROR(VLOOKUP(AA18,PointsMap!M2:N5,2,0),0) -> 0 | AF18: =IFERROR(VLOOKUP(Z18,PointsMap!J2:K5,2,0),0) -> 0 | AG18: =MIN(8,VALUE(T18)*2) -> 0 | AH18: =IFERROR(VLOOKUP(Q18,PointsMap!P2:Q5,2,0),0) -> 0 | AI18: =MIN(8,ROUND(VALUE(G18)*8,0)) -> 0 | AJ18: =IFERROR(VLOOKUP(I18,PointsMap!A2:B5,2,0),0) -> 0 | AK18: =IFERROR(VLOOKUP(W18,PointsMap!S2:T4,2,0),0) -> 0 | AL18: =IFERROR(VLOOKUP(X18,PointsMap!V2:W4,2,0),0) -> 0 | AM18: =MIN(5,VALUE(V18)) -> 0 | AN18: =AB18 -> 0 | AO18: =AC18+AD18+AE18+AF18 -> 0 | AP18: =AG18+AH18 -> 0 | AQ18: =AI18+AJ18 -> 0 | AR18: =AK18+AL18+AM18 -> 0 | AS18: =AN18*Weights!B3/100+AO18*Weights!B4/100+AP18*Weights!B5/100+AQ18*Weights!B6/100+AR18*Weights!B7/100 -> 0
A19: WONGDOODY (Infosys) | B19: https://www.wongdoody.com/ | C19: Subsidiary brand of public holding company | D19: 1993 | E19: 12 | F19: 500–1k | G19: 0.55 | H19: 0.25 | I19: Hybrid | J19: $250k–$1M | K19: N | L19: N | M19: Guidelines only | N19: Y | O19: 10 | P19: 8 | Q19: Low (1–3) | R19: 2 | S19: Asset generation | T19: 2 | U19: Commercial LLM | V19: 2 | W19: None | X19: Quarterly | Y19: Guidelines | Z19: None | AB19: =VALUE(R19)*6 -> 0 | AC19: =IFERROR(VLOOKUP(K19,PointsMap!D2:E3,2,0),0) -> 0 | AD19: =IFERROR(VLOOKUP(M19,PointsMap!G2:H5,2,0),0) -> 0 | AE19: =IFERROR(VLOOKUP(AA19,PointsMap!M2:N5,2,0),0) -> 0 | AF19: =IFERROR(VLOOKUP(Z19,PointsMap!J2:K5,2,0),0) -> 0 | AG19: =MIN(8,VALUE(T19)*2) -> 0 | AH19: =IFERROR(VLOOKUP(Q19,PointsMap!P2:Q5,2,0),0) -> 0 | AI19: =MIN(8,ROUND(VALUE(G19)*8,0)) -> 0 | AJ19: =IFERROR(VLOOKUP(I19,PointsMap!A2:B5,2,0),0) -> 0 | AK19: =IFERROR(VLOOKUP(W19,PointsMap!S2:T4,2,0),0) -> 0 | AL19: =IFERROR(VLOOKUP(X19,PointsMap!V2:W4,2,0),0) -> 0 | AM19: =MIN(5,VALUE(V19)) -> 0 | AN19: =AB19 -> 0 | AO19: =AC19+AD19+AE19+AF19 -> 0 | AP19: =AG19+AH19 -> 0 | AQ19: =AI19+AJ19 -> 0 | AR19: =AK19+AL19+AM19 -> 0 | AS19: =AN19*Weights!B3/100+AO19*Weights!B4/100+AP19*Weights!B5/100+AQ19*Weights!B6/100+AR19*Weights!B7/100 -> 0
A20: Tata Elxsi | B20: https://www.tataelxsi.com/ | C20: Public company | D20: 1989 | E20: 20 | F20: 5k–20k | G20: 0.3 | H20: 0.5 | I20: Hybrid | J20: $250k–$1M | K20: Y | L20: Y | M20: WCAG AA | N20: Y | O20: 25 | P20: 40 | Q20: Mid (4–9) | R20: 3 | S20: Component generation | T20: 3 | U20: Commercial LLM | V20: 70 | W20: Contributor | X20: Quarterly | Y20: Tokens/Multi-brand | Z20: A/B testing | AA20: SAST+DAST | AB20: =VALUE(R20)*6 -> 0 | AC20: =IFERROR(VLOOKUP(K20,PointsMap!D2:E3,2,0),0) -> 0 | AD20: =IFERROR(VLOOKUP(M20,PointsMap!G2:H5,2,0),0) -> 0 | AE20: =IFERROR(VLOOKUP(AA20,PointsMap!M2:N5,2,0),0) -> 0 | AF20: =IFERROR(VLOOKUP(Z20,PointsMap!J2:K5,2,0),0) -> 0 | AG20: =MIN(8,VALUE(T20)*2) -> 0 | AH20: =IFERROR(VLOOKUP(Q20,PointsMap!P2:Q5,2,0),0) -> 0 | AI20: =MIN(8,ROUND(VALUE(G20)*8,0)) -> 0 | AJ20: =IFERROR(VLOOKUP(I20,PointsMap!A2:B5,2,0),0) -> 0 | AK20: =IFERROR(VLOOKUP(W20,PointsMap!S2:T4,2,0),0) -> 0 | AL20: =IFERROR(VLOOKUP(X20,PointsMap!V2:W4,2,0),0) -> 0 | AM20: =MIN(5,VALUE(V20)) -> 0 | AN20: =AB20 -> 0 | AO20: =AC20+AD20+AE20+AF20 -> 0 | AP20: =AG20+AH20 -> 0 | AQ20: =AI20+AJ20 -> 0 | AR20: =AK20+AL20+AM20 -> 0 | AS20: =AN20*Weights!B3/100+AO20*Weights!B4/100+AP20*Weights!B5/100+AQ20*Weights!B6/100+AR20*Weights!B7/100 -> 0
A21: Cheil Worldwide | B21: https://www.cheil.com/ | C21: Public company | D21: 1973 | E21: 53 | F21: 5k–20k | G21: 0.35 | H21: 0.35 | I21: Hybrid | J21: $250k–$1M | K21: N | L21: N | M21: Guidelines only | N21: Y | O21: 30 | P21: 20 | Q21: Low (1–3) | R21: 2 | S21: Asset generation | T21: 2 | U21: Commercial LLM | V21: 5 | W21: None | X21: Quarterly | Y21: Guidelines | Z21: Event tracking | AA21: Lint/Static analysis | AB21: =VALUE(R21)*6 -> 0 | AC21: =IFERROR(VLOOKUP(K21,PointsMap!D2:E3,2,0),0) -> 0 | AD21: =IFERROR(VLOOKUP(M21,PointsMap!G2:H5,2,0),0) -> 0 | AE21: =IFERROR(VLOOKUP(AA21,PointsMap!M2:N5,2,0),0) -> 0 | AF21: =IFERROR(VLOOKUP(Z21,PointsMap!J2:K5,2,0),0) -> 0 | AG21: =MIN(8,VALUE(T21)*2) -> 0 | AH21: =IFERROR(VLOOKUP(Q21,PointsMap!P2:Q5,2,0),0) -> 0 | AI21: =MIN(8,ROUND(VALUE(G21)*8,0)) -> 0 | AJ21: =IFERROR(VLOOKUP(I21,PointsMap!A2:B5,2,0),0) -> 0 | AK21: =IFERROR(VLOOKUP(W21,PointsMap!S2:T4,2,0),0) -> 0 | AL21: =IFERROR(VLOOKUP(X21,PointsMap!V2:W4,2,0),0) -> 0 | AM21: =MIN(5,VALUE(V21)) -> 0 | AN21: =AB21 -> 0 | AO21: =AC21+AD21+AE21+AF21 -> 0 | AP21: =AG21+AH21 -> 0 | AQ21: =AI21+AJ21 -> 0 | AR21: =AK21+AL21+AM21 -> 0 | AS21: =AN21*Weights!B3/100+AO21*Weights!B4/100+AP21*Weights!B5/100+AQ21*Weights!B6/100+AR21*Weights!B7/100 -> 0
A22: McKinsey Design | B22: https://www.mckinsey.com/capabilities/design | C22: Business unit of private partnership | D22: 1926 | E22: 65 | F22: >20k | G22: 0.3 | H22: 0.35 | I22: Hybrid | J22: >$5M | K22: Y | L22: Y | M22: WCAG AA | N22: Y | O22: 35 | P22: 60 | Q22: Mid (4–9) | R22: 3 | S22: Component generation | T22: 3 | U22: Commercial LLM | W22: Contributor | X22: Monthly+ | Y22: Tokens/Multi-brand | Z22: A/B testing | AA22: SAST+DAST | AB22: =VALUE(R22)*6 -> 0 | AC22: =IFERROR(VLOOKUP(K22,PointsMap!D2:E3,2,0),0) -> 0 | AD22: =IFERROR(VLOOKUP(M22,PointsMap!G2:H5,2,0),0) -> 0 | AE22: =IFERROR(VLOOKUP(AA22,PointsMap!M2:N5,2,0),0) -> 0 | AF22: =IFERROR(VLOOKUP(Z22,PointsMap!J2:K5,2,0),0) -> 0 | AG22: =MIN(8,VALUE(T22)*2) -> 0 | AH22: =IFERROR(VLOOKUP(Q22,PointsMap!P2:Q5,2,0),0) -> 0 | AI22: =MIN(8,ROUND(VALUE(G22)*8,0)) -> 0 | AJ22: =IFERROR(VLOOKUP(I22,PointsMap!A2:B5,2,0),0) -> 0 | AK22: =IFERROR(VLOOKUP(W22,PointsMap!S2:T4,2,0),0) -> 0 | AL22: =IFERROR(VLOOKUP(X22,PointsMap!V2:W4,2,0),0) -> 0 | AM22: =MIN(5,VALUE(V22)) -> 0 | AN22: =AB22 -> 0 | AO22: =AC22+AD22+AE22+AF22 -> 0 | AP22: =AG22+AH22 -> 0 | AQ22: =AI22+AJ22 -> 0 | AR22: =AK22+AL22+AM22 -> 0 | AS22: =AN22*Weights!B3/100+AO22*Weights!B4/100+AP22*Weights!B5/100+AQ22*Weights!B6/100+AR22*Weights!B7/100 -> 0 | AT22: https://www.mckinsey.com/capabilities/quantumblack/overview | AY22: https://www.mckinsey.com/careers | AZ22: https://www.mckinsey.com/featured-insights/mckinsey-explainers/what-is-generative-ai | BA22: https://github.com/mckinsey | BB22: https://www.mckinsey.com/featured-insights | BD22: Design unit within McKinsey; QuantumBlack as AI practice (high-level).
A23: BCG X (incl. Design) | B23: https://www.bcg.com/x | C23: Business unit of private partnership | D23: 1963 | E23: 50 | F23: >20k | G23: 0.3 | H23: 0.4 | I23: Hybrid | J23: >$5M | K23: Y | L23: Y | M23: WCAG AA | N23: Y | O23: 30 | P23: 55 | Q23: Mid (4–9) | R23: 3 | S23: Component generation | T23: 3 | U23: Commercial + in-house RAG | W23: Contributor | X23: Monthly+ | Y23: Tokens/Multi-brand | Z23: A/B testing | AA23: SAST+DAST | AB23: =VALUE(R23)*6 -> 0 | AC23: =IFERROR(VLOOKUP(K23,PointsMap!D2:E3,2,0),0) -> 0 | AD23: =IFERROR(VLOOKUP(M23,PointsMap!G2:H5,2,0),0) -> 0 | AE23: =IFERROR(VLOOKUP(AA23,PointsMap!M2:N5,2,0),0) -> 0 | AF23: =IFERROR(VLOOKUP(Z23,PointsMap!J2:K5,2,0),0) -> 0 | AG23: =MIN(8,VALUE(T23)*2) -> 0 | AH23: =IFERROR(VLOOKUP(Q23,PointsMap!P2:Q5,2,0),0) -> 0 | AI23: =MIN(8,ROUND(VALUE(G23)*8,0)) -> 0 | AJ23: =IFERROR(VLOOKUP(I23,PointsMap!A2:B5,2,0),0) -> 0 | AK23: =IFERROR(VLOOKUP(W23,PointsMap!S2:T4,2,0),0) -> 0 | AL23: =IFERROR(VLOOKUP(X23,PointsMap!V2:W4,2,0),0) -> 0 | AM23: =MIN(5,VALUE(V23)) -> 0 | AN23: =AB23 -> 0 | AO23: =AC23+AD23+AE23+AF23 -> 0 | AP23: =AG23+AH23 -> 0 | AQ23: =AI23+AJ23 -> 0 | AR23: =AK23+AL23+AM23 -> 0 | AS23: =AN23*Weights!B3/100+AO23*Weights!B4/100+AP23*Weights!B5/100+AQ23*Weights!B6/100+AR23*Weights!B7/100 -> 0 | AT23: https://www.bcg.com/x | AY23: https://www.bcg.com/careers | BB23: https://www.bcg.com/insights | BD23: BCG X umbrella for build/AI.
A24: Bain & Company (Digital) | B24: https://www.bain.com/consulting/digital/ | C24: Business unit of private partnership | D24: 1973 | E24: 65 | F24: >20k | G24: 0.25 | H24: 0.35 | I24: Hybrid | J24: >$5M | K24: Y | L24: Y | M24: Guidelines only | N24: Y | O24: 25 | P24: 40 | Q24: Low (1–3) | R24: 2 | S24: Copy/Localization | T24: 2 | U24: Commercial LLM | W24: None | X24: Quarterly | Y24: Guidelines | Z24: Event tracking | AA24: Lint/Static analysis | AB24: =VALUE(R24)*6 -> 0 | AC24: =IFERROR(VLOOKUP(K24,PointsMap!D2:E3,2,0),0) -> 0 | AD24: =IFERROR(VLOOKUP(M24,PointsMap!G2:H5,2,0),0) -> 0 | AE24: =IFERROR(VLOOKUP(AA24,PointsMap!M2:N5,2,0),0) -> 0 | AF24: =IFERROR(VLOOKUP(Z24,PointsMap!J2:K5,2,0),0) -> 0 | AG24: =MIN(8,VALUE(T24)*2) -> 0 | AH24: =IFERROR(VLOOKUP(Q24,PointsMap!P2:Q5,2,0),0) -> 0 | AI24: =MIN(8,ROUND(VALUE(G24)*8,0)) -> 0 | AJ24: =IFERROR(VLOOKUP(I24,PointsMap!A2:B5,2,0),0) -> 0 | AK24: =IFERROR(VLOOKUP(W24,PointsMap!S2:T4,2,0),0) -> 0 | AL24: =IFERROR(VLOOKUP(X24,PointsMap!V2:W4,2,0),0) -> 0 | AM24: =MIN(5,VALUE(V24)) -> 0 | AN24: =AB24 -> 0 | AO24: =AC24+AD24+AE24+AF24 -> 0 | AP24: =AG24+AH24 -> 0 | AQ24: =AI24+AJ24 -> 0 | AR24: =AK24+AL24+AM24 -> 0 | AS24: =AN24*Weights!B3/100+AO24*Weights!B4/100+AP24*Weights!B5/100+AQ24*Weights!B6/100+AR24*Weights!B7/100 -> 0 | AT24: https://www.bain.com/consulting/enterprise-technology/advanced-analytics/ | AY24: https://www.bain.com/careers/ | BB24: https://www.bain.com/insights/ | BD24: Advanced analytics/AI pages; insights.
A25: PwC Experience Center | B25: https://www.pwc.com/ | C25: Multinational network of independent member firms | D25: 1849 | E25: 150 | F25: >20k | G25: 0.3 | H25: 0.3 | I25: Hybrid | J25: >$5M | K25: Y | L25: Y | M25: WCAG AA | N25: Y | O25: 40 | P25: 60 | Q25: Mid (4–9) | R25: 3 | S25: Component generation | T25: 3 | U25: Commercial LLM | W25: Contributor | X25: Monthly+ | Y25: Tokens/Multi-brand | Z25: A/B testing | AA25: SAST+DAST | AB25: =VALUE(R25)*6 -> 0 | AC25: =IFERROR(VLOOKUP(K25,PointsMap!D2:E3,2,0),0) -> 0 | AD25: =IFERROR(VLOOKUP(M25,PointsMap!G2:H5,2,0),0) -> 0 | AE25: =IFERROR(VLOOKUP(AA25,PointsMap!M2:N5,2,0),0) -> 0 | AF25: =IFERROR(VLOOKUP(Z25,PointsMap!J2:K5,2,0),0) -> 0 | AG25: =MIN(8,VALUE(T25)*2) -> 0 | AH25: =IFERROR(VLOOKUP(Q25,PointsMap!P2:Q5,2,0),0) -> 0 | AI25: =MIN(8,ROUND(VALUE(G25)*8,0)) -> 0 | AJ25: =IFERROR(VLOOKUP(I25,PointsMap!A2:B5,2,0),0) -> 0 | AK25: =IFERROR(VLOOKUP(W25,PointsMap!S2:T4,2,0),0) -> 0 | AL25: =IFERROR(VLOOKUP(X25,PointsMap!V2:W4,2,0),0) -> 0 | AM25: =MIN(5,VALUE(V25)) -> 0 | AN25: =AB25 -> 0 | AO25: =AC25+AD25+AE25+AF25 -> 0 | AP25: =AG25+AH25 -> 0 | AQ25: =AI25+AJ25 -> 0 | AR25: =AK25+AL25+AM25 -> 0 | AS25: =AN25*Weights!B3/100+AO25*Weights!B4/100+AP25*Weights!B5/100+AQ25*Weights!B6/100+AR25*Weights!B7/100 -> 0 | AT25: https://www.pwc.com/gx/en/issues/analytics/artificial-intelligence.html | AY25: https://www.pwc.com/careers | BB25: https://www.pwc.com/gx/en/insights.html | BD25: Global AI/analytics hub.
A26: EY wavespace | B26: https://www.ey.com/ | C26: Multinational network of independent member firms | D26: 1989 | E26: 120 | F26: >20k | G26: 0.3 | H26: 0.3 | I26: Hybrid | J26: >$5M | K26: Y | L26: Y | M26: Guidelines only | N26: Y | O26: 30 | P26: 45 | Q26: Low (1–3) | R26: 2 | S26: Copy/Localization | T26: 2 | U26: Commercial LLM | W26: None | X26: Quarterly | Y26: Guidelines | Z26: Event tracking | AA26: Lint/Static analysis | AB26: =VALUE(R26)*6 -> 0 | AC26: =IFERROR(VLOOKUP(K26,PointsMap!D2:E3,2,0),0) -> 0 | AD26: =IFERROR(VLOOKUP(M26,PointsMap!G2:H5,2,0),0) -> 0 | AE26: =IFERROR(VLOOKUP(AA26,PointsMap!M2:N5,2,0),0) -> 0 | AF26: =IFERROR(VLOOKUP(Z26,PointsMap!J2:K5,2,0),0) -> 0 | AG26: =MIN(8,VALUE(T26)*2) -> 0 | AH26: =IFERROR(VLOOKUP(Q26,PointsMap!P2:Q5,2,0),0) -> 0 | AI26: =MIN(8,ROUND(VALUE(G26)*8,0)) -> 0 | AJ26: =IFERROR(VLOOKUP(I26,PointsMap!A2:B5,2,0),0) -> 0 | AK26: =IFERROR(VLOOKUP(W26,PointsMap!S2:T4,2,0),0) -> 0 | AL26: =IFERROR(VLOOKUP(X26,PointsMap!V2:W4,2,0),0) -> 0 | AM26: =MIN(5,VALUE(V26)) -> 0 | AN26: =AB26 -> 0 | AO26: =AC26+AD26+AE26+AF26 -> 0 | AP26: =AG26+AH26 -> 0 | AQ26: =AI26+AJ26 -> 0 | AR26: =AK26+AL26+AM26 -> 0 | AS26: =AN26*Weights!B3/100+AO26*Weights!B4/100+AP26*Weights!B5/100+AQ26*Weights!B6/100+AR26*Weights!B7/100 -> 0 | AT26: https://www.ey.com/en_gl/alliances/ai | AY26: https://www.ey.com/en_gl/careers | BB26: https://www.ey.com/en_gl/insights | BD26: AI alliances & insights.
A27: KPMG Experience Design | B27: https://kpmg.com/ | C27: Multinational network of independent member firms | D27: 1987 | E27: 120 | F27: >20k | G27: 0.3 | H27: 0.3 | I27: Hybrid | J27: >$5M | K27: Y | L27: Y | M27: WCAG AA | N27: Y | O27: 30 | P27: 40 | Q27: Low (1–3) | R27: 2 | S27: Copy/Localization | T27: 2 | U27: Commercial LLM | W27: None | X27: Quarterly | Y27: Guidelines | Z27: Event tracking | AA27: Lint/Static analysis | AB27: =VALUE(R27)*6 -> 0 | AC27: =IFERROR(VLOOKUP(K27,PointsMap!D2:E3,2,0),0) -> 0 | AD27: =IFERROR(VLOOKUP(M27,PointsMap!G2:H5,2,0),0) -> 0 | AE27: =IFERROR(VLOOKUP(AA27,PointsMap!M2:N5,2,0),0) -> 0 | AF27: =IFERROR(VLOOKUP(Z27,PointsMap!J2:K5,2,0),0) -> 0 | AG27: =MIN(8,VALUE(T27)*2) -> 0 | AH27: =IFERROR(VLOOKUP(Q27,PointsMap!P2:Q5,2,0),0) -> 0 | AI27: =MIN(8,ROUND(VALUE(G27)*8,0)) -> 0 | AJ27: =IFERROR(VLOOKUP(I27,PointsMap!A2:B5,2,0),0) -> 0 | AK27: =IFERROR(VLOOKUP(W27,PointsMap!S2:T4,2,0),0) -> 0 | AL27: =IFERROR(VLOOKUP(X27,PointsMap!V2:W4,2,0),0) -> 0 | AM27: =MIN(5,VALUE(V27)) -> 0 | AN27: =AB27 -> 0 | AO27: =AC27+AD27+AE27+AF27 -> 0 | AP27: =AG27+AH27 -> 0 | AQ27: =AI27+AJ27 -> 0 | AR27: =AK27+AL27+AM27 -> 0 | AS27: =AN27*Weights!B3/100+AO27*Weights!B4/100+AP27*Weights!B5/100+AQ27*Weights!B6/100+AR27*Weights!B7/100 -> 0 | AT27: https://kpmg.com/xx/en/home/services/technology/artificial-intelligence.html | AY27: https://kpmg.com/careers | BB27: https://kpmg.com/xx/en/home/insights.html | BD27: AI services overview.
A28: Cognizant Digital Experience | B28: https://www.cognizant.com/ | C28: Business unit of public company | D28: 1994 | E28: 90 | F28: >20k | G28: 0.3 | H28: 0.5 | I28: Distributed nearshore/offshore | J28: $1M–$5M | K28: Y | L28: Y | M28: WCAG AA | N28: Y | O28: 60 | P28: 120 | Q28: High (10+) | R28: 4 | S28: Component generation | T28: 4 | U28: Commercial + in-house RAG | W28: Contributor | X28: Monthly+ | Y28: Tokens/Multi-brand | Z28: A/B testing | AA28: SAST+DAST | AB28: =VALUE(R28)*6 -> 0 | AC28: =IFERROR(VLOOKUP(K28,PointsMap!D2:E3,2,0),0) -> 0 | AD28: =IFERROR(VLOOKUP(M28,PointsMap!G2:H5,2,0),0) -> 0 | AE28: =IFERROR(VLOOKUP(AA28,PointsMap!M2:N5,2,0),0) -> 0 | AF28: =IFERROR(VLOOKUP(Z28,PointsMap!J2:K5,2,0),0) -> 0 | AG28: =MIN(8,VALUE(T28)*2) -> 0 | AH28: =IFERROR(VLOOKUP(Q28,PointsMap!P2:Q5,2,0),0) -> 0 | AI28: =MIN(8,ROUND(VALUE(G28)*8,0)) -> 0 | AJ28: =IFERROR(VLOOKUP(I28,PointsMap!A2:B5,2,0),0) -> 0 | AK28: =IFERROR(VLOOKUP(W28,PointsMap!S2:T4,2,0),0) -> 0 | AL28: =IFERROR(VLOOKUP(X28,PointsMap!V2:W4,2,0),0) -> 0 | AM28: =MIN(5,VALUE(V28)) -> 0 | AN28: =AB28 -> 0 | AO28: =AC28+AD28+AE28+AF28 -> 0 | AP28: =AG28+AH28 -> 0 | AQ28: =AI28+AJ28 -> 0 | AR28: =AK28+AL28+AM28 -> 0 | AS28: =AN28*Weights!B3/100+AO28*Weights!B4/100+AP28*Weights!B5/100+AQ28*Weights!B6/100+AR28*Weights!B7/100 -> 0 | AT28: https://www.cognizant.com/us/en/services/ai | AU28: https://www.cognizant.com/us/en/about-cognizant/trust-center | AW28: https://www.cognizant.com/us/en/about-cognizant/trust-center | AY28: https://careers.cognizant.com/ | BA28: https://github.com/CognizantOpenSource | BB28: https://www.cognizant.com/us/en/insights | BD28: Trust Center; AI services; OSS org.
A29: Infosys (Digital Experience) | B29: https://www.infosys.com/ | C29: Business unit of public company | D29: 1981 | E29: 85 | F29: >20k | G29: 0.25 | H29: 0.55 | I29: Distributed nearshore/offshore | J29: $1M–$5M | K29: Y | L29: Y | M29: WCAG AA | N29: Y | O29: 55 | P29: 110 | Q29: High (10+) | R29: 4 | S29: Component generation | T29: 4 | U29: Commercial + in-house RAG | W29: Contributor | X29: Monthly+ | Y29: Tokens/Multi-brand | Z29: A/B testing | AA29: SAST+DAST | AB29: =VALUE(R29)*6 -> 0 | AC29: =IFERROR(VLOOKUP(K29,PointsMap!D2:E3,2,0),0) -> 0 | AD29: =IFERROR(VLOOKUP(M29,PointsMap!G2:H5,2,0),0) -> 0 | AE29: =IFERROR(VLOOKUP(AA29,PointsMap!M2:N5,2,0),0) -> 0 | AF29: =IFERROR(VLOOKUP(Z29,PointsMap!J2:K5,2,0),0) -> 0 | AG29: =MIN(8,VALUE(T29)*2) -> 0 | AH29: =IFERROR(VLOOKUP(Q29,PointsMap!P2:Q5,2,0),0) -> 0 | AI29: =MIN(8,ROUND(VALUE(G29)*8,0)) -> 0 | AJ29: =IFERROR(VLOOKUP(I29,PointsMap!A2:B5,2,0),0) -> 0 | AK29: =IFERROR(VLOOKUP(W29,PointsMap!S2:T4,2,0),0) -> 0 | AL29: =IFERROR(VLOOKUP(X29,PointsMap!V2:W4,2,0),0) -> 0 | AM29: =MIN(5,VALUE(V29)) -> 0 | AN29: =AB29 -> 0 | AO29: =AC29+AD29+AE29+AF29 -> 0 | AP29: =AG29+AH29 -> 0 | AQ29: =AI29+AJ29 -> 0 | AR29: =AK29+AL29+AM29 -> 0 | AS29: =AN29*Weights!B3/100+AO29*Weights!B4/100+AP29*Weights!B5/100+AQ29*Weights!B6/100+AR29*Weights!B7/100 -> 0 | AT29: https://www.infosys.com/services/data-analytics/offerings/generative-ai.html | AU29: https://www.infosys.com/trust-center/information-security.html | AW29: https://www.infosys.com/services/cyber-security | AY29: https://www.infosys.com/careers/apply.html | BA29: https://github.com/infosys | BB29: https://www.infosys.com/insights | BD29: Trust center; GenAI page; OSS.
A30: Wipro Design | B30: https://www.wipro.com/ | C30: Business unit of public company | D30: 1945 | E30: 70 | F30: >20k | G30: 0.3 | H30: 0.45 | I30: Distributed nearshore/offshore | J30: $1M–$5M | K30: Y | L30: Y | M30: WCAG AA | N30: Y | O30: 40 | P30: 80 | Q30: Mid (4–9) | R30: 3 | S30: Copy/Localization | T30: 3 | U30: Commercial LLM | W30: Contributor | X30: Quarterly | Y30: Tokens/Multi-brand | Z30: A/B testing | AA30: Lint/Static analysis | AB30: =VALUE(R30)*6 -> 0 | AC30: =IFERROR(VLOOKUP(K30,PointsMap!D2:E3,2,0),0) -> 0 | AD30: =IFERROR(VLOOKUP(M30,PointsMap!G2:H5,2,0),0) -> 0 | AE30: =IFERROR(VLOOKUP(AA30,PointsMap!M2:N5,2,0),0) -> 0 | AF30: =IFERROR(VLOOKUP(Z30,PointsMap!J2:K5,2,0),0) -> 0 | AG30: =MIN(8,VALUE(T30)*2) -> 0 | AH30: =IFERROR(VLOOKUP(Q30,PointsMap!P2:Q5,2,0),0) -> 0 | AI30: =MIN(8,ROUND(VALUE(G30)*8,0)) -> 0 | AJ30: =IFERROR(VLOOKUP(I30,PointsMap!A2:B5,2,0),0) -> 0 | AK30: =IFERROR(VLOOKUP(W30,PointsMap!S2:T4,2,0),0) -> 0 | AL30: =IFERROR(VLOOKUP(X30,PointsMap!V2:W4,2,0),0) -> 0 | AM30: =MIN(5,VALUE(V30)) -> 0 | AN30: =AB30 -> 0 | AO30: =AC30+AD30+AE30+AF30 -> 0 | AP30: =AG30+AH30 -> 0 | AQ30: =AI30+AJ30 -> 0 | AR30: =AK30+AL30+AM30 -> 0 | AS30: =AN30*Weights!B3/100+AO30*Weights!B4/100+AP30*Weights!B5/100+AQ30*Weights!B6/100+AR30*Weights!B7/100 -> 0 | AT30: https://www.wipro.com/ai/ | AU30: https://www.wipro.com/service-nets/information-security/ | AY30: https://careers.wipro.com/ | BA30: https://github.com/WiproOpenSource | BB30: https://www.wipro.com/insights/ | BD30: AI hub; InfoSec; OSS.
A31: HCLTech Digital | B31: https://www.hcltech.com/ | C31: Business unit of public company | D31: 1976 | E31: 60 | F31: >20k | G31: 0.25 | H31: 0.55 | I31: Distributed nearshore/offshore | J31: $1M–$5M | K31: Y | L31: Y | M31: Guidelines only | N31: Y | O31: 35 | P31: 70 | Q31: Mid (4–9) | R31: 3 | S31: Copy/Localization | T31: 3 | U31: Commercial LLM | W31: None | X31: Quarterly | Y31: Guidelines | Z31: Event tracking | AA31: Lint/Static analysis | AB31: =VALUE(R31)*6 -> 0 | AC31: =IFERROR(VLOOKUP(K31,PointsMap!D2:E3,2,0),0) -> 0 | AD31: =IFERROR(VLOOKUP(M31,PointsMap!G2:H5,2,0),0) -> 0 | AE31: =IFERROR(VLOOKUP(AA31,PointsMap!M2:N5,2,0),0) -> 0 | AF31: =IFERROR(VLOOKUP(Z31,PointsMap!J2:K5,2,0),0) -> 0 | AG31: =MIN(8,VALUE(T31)*2) -> 0 | AH31: =IFERROR(VLOOKUP(Q31,PointsMap!P2:Q5,2,0),0) -> 0 | AI31: =MIN(8,ROUND(VALUE(G31)*8,0)) -> 0 | AJ31: =IFERROR(VLOOKUP(I31,PointsMap!A2:B5,2,0),0) -> 0 | AK31: =IFERROR(VLOOKUP(W31,PointsMap!S2:T4,2,0),0) -> 0 | AL31: =IFERROR(VLOOKUP(X31,PointsMap!V2:W4,2,0),0) -> 0 | AM31: =MIN(5,VALUE(V31)) -> 0 | AN31: =AB31 -> 0 | AO31: =AC31+AD31+AE31+AF31 -> 0 | AP31: =AG31+AH31 -> 0 | AQ31: =AI31+AJ31 -> 0 | AR31: =AK31+AL31+AM31 -> 0 | AS31: =AN31*Weights!B3/100+AO31*Weights!B4/100+AP31*Weights!B5/100+AQ31*Weights!B6/100+AR31*Weights!B7/100 -> 0 | AT31: https://www.hcltech.com/ai | AY31: https://www.hcltech.com/careers | BA31: https://github.com/hcltech | BB31: https://www.hcltech.com/blogs | BD31: AI landing; careers; blog; OSS.
A32: TCS Interactive | B32: https://www.tcs.com/what-we-do/services/interactive | C32: Business unit of public company | D32: 1968 | E32: 100 | F32: >20k | G32: 0.25 | H32: 0.55 | I32: Distributed nearshore/offshore | J32: $1M–$5M | K32: Y | L32: Y | M32: WCAG AA | N32: Y | O32: 70 | P32: 130 | Q32: High (10+) | R32: 4 | S32: Component generation | T32: 4 | U32: Commercial + in-house RAG | W32: Contributor | X32: Monthly+ | Y32: Tokens/Multi-brand | Z32: A/B testing | AA32: SAST+DAST | AB32: =VALUE(R32)*6 -> 0 | AC32: =IFERROR(VLOOKUP(K32,PointsMap!D2:E3,2,0),0) -> 0 | AD32: =IFERROR(VLOOKUP(M32,PointsMap!G2:H5,2,0),0) -> 0 | AE32: =IFERROR(VLOOKUP(AA32,PointsMap!M2:N5,2,0),0) -> 0 | AF32: =IFERROR(VLOOKUP(Z32,PointsMap!J2:K5,2,0),0) -> 0 | AG32: =MIN(8,VALUE(T32)*2) -> 0 | AH32: =IFERROR(VLOOKUP(Q32,PointsMap!P2:Q5,2,0),0) -> 0 | AI32: =MIN(8,ROUND(VALUE(G32)*8,0)) -> 0 | AJ32: =IFERROR(VLOOKUP(I32,PointsMap!A2:B5,2,0),0) -> 0 | AK32: =IFERROR(VLOOKUP(W32,PointsMap!S2:T4,2,0),0) -> 0 | AL32: =IFERROR(VLOOKUP(X32,PointsMap!V2:W4,2,0),0) -> 0 | AM32: =MIN(5,VALUE(V32)) -> 0 | AN32: =AB32 -> 0 | AO32: =AC32+AD32+AE32+AF32 -> 0 | AP32: =AG32+AH32 -> 0 | AQ32: =AI32+AJ32 -> 0 | AR32: =AK32+AL32+AM32 -> 0 | AS32: =AN32*Weights!B3/100+AO32*Weights!B4/100+AP32*Weights!B5/100+AQ32*Weights!B6/100+AR32*Weights!B7/100 -> 0 | AT32: https://www.tcs.com/what-we-do/services/ai-cloud | AU32: https://www.tcs.com/who-we-are/security-trust | AY32: https://www.tcs.com/careers | BA32: https://github.com/TCS-Research | BB32: https://www.tcs.com/insights | BD32: AI & Cloud services; Trust page; Research GitHub.
A33: NTT DATA Design (Tangity) | B33: https://www.tangity.design/ | C33: Business unit of public company | D33: 1988 | E33: 60 | F33: >20k | G33: 0.35 | H33: 0.45 | I33: Hybrid | J33: $1M–$5M | K33: Y | L33: Y | M33: WCAG AA | N33: Y | O33: 30 | P33: 50 | Q33: Mid (4–9) | R33: 3 | S33: Copy/Localization | T33: 3 | U33: Commercial LLM | W33: Contributor | X33: Quarterly | Y33: Tokens/Multi-brand | Z33: A/B testing | AA33: Lint/Static analysis | AB33: =VALUE(R33)*6 -> 0 | AC33: =IFERROR(VLOOKUP(K33,PointsMap!D2:E3,2,0),0) -> 0 | AD33: =IFERROR(VLOOKUP(M33,PointsMap!G2:H5,2,0),0) -> 0 | AE33: =IFERROR(VLOOKUP(AA33,PointsMap!M2:N5,2,0),0) -> 0 | AF33: =IFERROR(VLOOKUP(Z33,PointsMap!J2:K5,2,0),0) -> 0 | AG33: =MIN(8,VALUE(T33)*2) -> 0 | AH33: =IFERROR(VLOOKUP(Q33,PointsMap!P2:Q5,2,0),0) -> 0 | AI33: =MIN(8,ROUND(VALUE(G33)*8,0)) -> 0 | AJ33: =IFERROR(VLOOKUP(I33,PointsMap!A2:B5,2,0),0) -> 0 | AK33: =IFERROR(VLOOKUP(W33,PointsMap!S2:T4,2,0),0) -> 0 | AL33: =IFERROR(VLOOKUP(X33,PointsMap!V2:W4,2,0),0) -> 0 | AM33: =MIN(5,VALUE(V33)) -> 0 | AN33: =AB33 -> 0 | AO33: =AC33+AD33+AE33+AF33 -> 0 | AP33: =AG33+AH33 -> 0 | AQ33: =AI33+AJ33 -> 0 | AR33: =AK33+AL33+AM33 -> 0 | AS33: =AN33*Weights!B3/100+AO33*Weights!B4/100+AP33*Weights!B5/100+AQ33*Weights!B6/100+AR33*Weights!B7/100 -> 0 | AT33: https://www.nttdata.com/global/en/offerings/advisory/ai | AY33: https://www.nttdata.com/global/en/careers | BA33: https://github.com/nttdata | BB33: https://www.nttdata.com/global/en/insights | BD33: Global AI offerings page.
A34: Isobar (Dentsu Creative) | B34: https://www.dentsu.com/ | C34: Subsidiary brand of public holding company | D34: 1901 | E34: 50 | F34: 5k–20k | G34: 0.45 | H34: 0.3 | I34: Hybrid | J34: $250k–$1M | K34: N | L34: N | M34: Guidelines only | N34: Y | O34: 20 | P34: 20 | Q34: Low (1–3) | R34: 2 | S34: Asset generation | T34: 2 | U34: Commercial LLM | W34: None | X34: Quarterly | Y34: Guidelines | Z34: Event tracking | AA34: None | AB34: =VALUE(R34)*6 -> 0 | AC34: =IFERROR(VLOOKUP(K34,PointsMap!D2:E3,2,0),0) -> 0 | AD34: =IFERROR(VLOOKUP(M34,PointsMap!G2:H5,2,0),0) -> 0 | AE34: =IFERROR(VLOOKUP(AA34,PointsMap!M2:N5,2,0),0) -> 0 | AF34: =IFERROR(VLOOKUP(Z34,PointsMap!J2:K5,2,0),0) -> 0 | AG34: =MIN(8,VALUE(T34)*2) -> 0 | AH34: =IFERROR(VLOOKUP(Q34,PointsMap!P2:Q5,2,0),0) -> 0 | AI34: =MIN(8,ROUND(VALUE(G34)*8,0)) -> 0 | AJ34: =IFERROR(VLOOKUP(I34,PointsMap!A2:B5,2,0),0) -> 0 | AK34: =IFERROR(VLOOKUP(W34,PointsMap!S2:T4,2,0),0) -> 0 | AL34: =IFERROR(VLOOKUP(X34,PointsMap!V2:W4,2,0),0) -> 0 | AM34: =MIN(5,VALUE(V34)) -> 0 | AN34: =AB34 -> 0 | AO34: =AC34+AD34+AE34+AF34 -> 0 | AP34: =AG34+AH34 -> 0 | AQ34: =AI34+AJ34 -> 0 | AR34: =AK34+AL34+AM34 -> 0 | AS34: =AN34*Weights!B3/100+AO34*Weights!B4/100+AP34*Weights!B5/100+AQ34*Weights!B6/100+AR34*Weights!B7/100 -> 0 | AT34: https://www.dentsu.com/services/creative | AY34: https://www.dentsu.com/careers | BB34: https://www.dentsu.com/our-thinking | BD34: Dentsu creative/tech umbrella.
A35: VML (WPP) | B35: https://www.vml.com/ | C35: Subsidiary brand of public holding company | D35: 2023 | E35: 60 | F35: 5k–20k | G35: 0.5 | H35: 0.3 | I35: Hybrid | J35: $250k–$1M | K35: N | L35: N | M35: Guidelines only | N35: Y | O35: 25 | P35: 25 | Q35: Low (1–3) | R35: 2 | S35: Asset generation | T35: 2 | U35: Commercial LLM | W35: Contributor | X35: Monthly+ | Y35: Guidelines | Z35: Event tracking | AA35: Lint/Static analysis | AB35: =VALUE(R35)*6 -> 0 | AC35: =IFERROR(VLOOKUP(K35,PointsMap!D2:E3,2,0),0) -> 0 | AD35: =IFERROR(VLOOKUP(M35,PointsMap!G2:H5,2,0),0) -> 0 | AE35: =IFERROR(VLOOKUP(AA35,PointsMap!M2:N5,2,0),0) -> 0 | AF35: =IFERROR(VLOOKUP(Z35,PointsMap!J2:K5,2,0),0) -> 0 | AG35: =MIN(8,VALUE(T35)*2) -> 0 | AH35: =IFERROR(VLOOKUP(Q35,PointsMap!P2:Q5,2,0),0) -> 0 | AI35: =MIN(8,ROUND(VALUE(G35)*8,0)) -> 0 | AJ35: =IFERROR(VLOOKUP(I35,PointsMap!A2:B5,2,0),0) -> 0 | AK35: =IFERROR(VLOOKUP(W35,PointsMap!S2:T4,2,0),0) -> 0 | AL35: =IFERROR(VLOOKUP(X35,PointsMap!V2:W4,2,0),0) -> 0 | AM35: =MIN(5,VALUE(V35)) -> 0 | AN35: =AB35 -> 0 | AO35: =AC35+AD35+AE35+AF35 -> 0 | AP35: =AG35+AH35 -> 0 | AQ35: =AI35+AJ35 -> 0 | AR35: =AK35+AL35+AM35 -> 0 | AS35: =AN35*Weights!B3/100+AO35*Weights!B4/100+AP35*Weights!B5/100+AQ35*Weights!B6/100+AR35*Weights!B7/100 -> 0 | AT35: https://www.vml.com/services/technology | AY35: https://www.vml.com/careers | BB35: https://www.vml.com/insights | BD35: Tech services page.
A36: Ogilvy Experience | B36: https://www.ogilvy.com/ | C36: Subsidiary brand of public holding company | D36: 1948 | E36: 50 | F36: 5k–20k | G36: 0.5 | H36: 0.25 | I36: Hybrid | J36: $250k–$1M | K36: N | L36: N | M36: Guidelines only | N36: Y | O36: 25 | P36: 20 | Q36: Low (1–3) | R36: 2 | S36: Copy/Localization | T36: 2 | U36: Commercial LLM | W36: None | X36: Quarterly | Y36: Guidelines | Z36: Event tracking | AA36: None | AB36: =VALUE(R36)*6 -> 0 | AC36: =IFERROR(VLOOKUP(K36,PointsMap!D2:E3,2,0),0) -> 0 | AD36: =IFERROR(VLOOKUP(M36,PointsMap!G2:H5,2,0),0) -> 0 | AE36: =IFERROR(VLOOKUP(AA36,PointsMap!M2:N5,2,0),0) -> 0 | AF36: =IFERROR(VLOOKUP(Z36,PointsMap!J2:K5,2,0),0) -> 0 | AG36: =MIN(8,VALUE(T36)*2) -> 0 | AH36: =IFERROR(VLOOKUP(Q36,PointsMap!P2:Q5,2,0),0) -> 0 | AI36: =MIN(8,ROUND(VALUE(G36)*8,0)) -> 0 | AJ36: =IFERROR(VLOOKUP(I36,PointsMap!A2:B5,2,0),0) -> 0 | AK36: =IFERROR(VLOOKUP(W36,PointsMap!S2:T4,2,0),0) -> 0 | AL36: =IFERROR(VLOOKUP(X36,PointsMap!V2:W4,2,0),0) -> 0 | AM36: =MIN(5,VALUE(V36)) -> 0 | AN36: =AB36 -> 0 | AO36: =AC36+AD36+AE36+AF36 -> 0 | AP36: =AG36+AH36 -> 0 | AQ36: =AI36+AJ36 -> 0 | AR36: =AK36+AL36+AM36 -> 0 | AS36: =AN36*Weights!B3/100+AO36*Weights!B4/100+AP36*Weights!B5/100+AQ36*Weights!B6/100+AR36*Weights!B7/100 -> 0 | AT36: https://www.ogilvy.com/capabilities/consulting | AY36: https://www.ogilvy.com/careers | BB36: https://www.ogilvy.com/ideas | BD36: Consulting/experience capability.
A37: Razorfish (Publicis) | B37: https://www.razorfish.com/ | C37: Subsidiary brand of public holding company | D37: 1995 | E37: 15 | F37: 1–5k | G37: 0.55 | H37: 0.25 | I37: Hybrid | J37: $250k–$1M | K37: N | L37: N | M37: WCAG AA | N37: Y | O37: 15 | P37: 12 | Q37: Low (1–3) | R37: 2 | S37: Copy/Localization | T37: 2 | U37: Commercial LLM | W37: Contributor | X37: Monthly+ | Y37: Guidelines | Z37: A/B testing | AA37: Lint/Static analysis | AB37: =VALUE(R37)*6 -> 0 | AC37: =IFERROR(VLOOKUP(K37,PointsMap!D2:E3,2,0),0) -> 0 | AD37: =IFERROR(VLOOKUP(M37,PointsMap!G2:H5,2,0),0) -> 0 | AE37: =IFERROR(VLOOKUP(AA37,PointsMap!M2:N5,2,0),0) -> 0 | AF37: =IFERROR(VLOOKUP(Z37,PointsMap!J2:K5,2,0),0) -> 0 | AG37: =MIN(8,VALUE(T37)*2) -> 0 | AH37: =IFERROR(VLOOKUP(Q37,PointsMap!P2:Q5,2,0),0) -> 0 | AI37: =MIN(8,ROUND(VALUE(G37)*8,0)) -> 0 | AJ37: =IFERROR(VLOOKUP(I37,PointsMap!A2:B5,2,0),0) -> 0 | AK37: =IFERROR(VLOOKUP(W37,PointsMap!S2:T4,2,0),0) -> 0 | AL37: =IFERROR(VLOOKUP(X37,PointsMap!V2:W4,2,0),0) -> 0 | AM37: =MIN(5,VALUE(V37)) -> 0 | AN37: =AB37 -> 0 | AO37: =AC37+AD37+AE37+AF37 -> 0 | AP37: =AG37+AH37 -> 0 | AQ37: =AI37+AJ37 -> 0 | AR37: =AK37+AL37+AM37 -> 0 | AS37: =AN37*Weights!B3/100+AO37*Weights!B4/100+AP37*Weights!B5/100+AQ37*Weights!B6/100+AR37*Weights!B7/100 -> 0 | AT37: https://www.razorfish.com/capabilities/technology | AY37: https://www.razorfish.com/careers | BB37: https://www.razorfish.com/ideas | BD37: Tech capability and ideas.
A38: Havas CX | B38: https://www.havascx.com/ | C38: Subsidiary brand of private holding company | D38: 1835 | E38: 20 | F38: 1–5k | G38: 0.55 | H38: 0.25 | I38: Hybrid | J38: $250k–$1M | K38: N | L38: N | M38: Guidelines only | N38: Y | O38: 12 | P38: 8 | Q38: Low (1–3) | R38: 2 | S38: Asset generation | T38: 2 | U38: Commercial LLM | W38: None | X38: Quarterly | Y38: Guidelines | Z38: Event tracking | AA38: None | AB38: =VALUE(R38)*6 -> 0 | AC38: =IFERROR(VLOOKUP(K38,PointsMap!D2:E3,2,0),0) -> 0 | AD38: =IFERROR(VLOOKUP(M38,PointsMap!G2:H5,2,0),0) -> 0 | AE38: =IFERROR(VLOOKUP(AA38,PointsMap!M2:N5,2,0),0) -> 0 | AF38: =IFERROR(VLOOKUP(Z38,PointsMap!J2:K5,2,0),0) -> 0 | AG38: =MIN(8,VALUE(T38)*2) -> 0 | AH38: =IFERROR(VLOOKUP(Q38,PointsMap!P2:Q5,2,0),0) -> 0 | AI38: =MIN(8,ROUND(VALUE(G38)*8,0)) -> 0 | AJ38: =IFERROR(VLOOKUP(I38,PointsMap!A2:B5,2,0),0) -> 0 | AK38: =IFERROR(VLOOKUP(W38,PointsMap!S2:T4,2,0),0) -> 0 | AL38: =IFERROR(VLOOKUP(X38,PointsMap!V2:W4,2,0),0) -> 0 | AM38: =MIN(5,VALUE(V38)) -> 0 | AN38: =AB38 -> 0 | AO38: =AC38+AD38+AE38+AF38 -> 0 | AP38: =AG38+AH38 -> 0 | AQ38: =AI38+AJ38 -> 0 | AR38: =AK38+AL38+AM38 -> 0 | AS38: =AN38*Weights!B3/100+AO38*Weights!B4/100+AP38*Weights!B5/100+AQ38*Weights!B6/100+AR38*Weights!B7/100 -> 0 | AT38: https://www.havas.com/our-capabilities | AY38: https://www.havas.com/careers | BB38: https://www.havas.com/news/ | BD38: Group capability hub.
A39: Code and Theory (Stagwell) | B39: https://www.codeandtheory.com/ | C39: Subsidiary brand of public holding company | D39: 2001 | E39: 10 | F39: 1–5k | G39: 0.6 | H39: 0.25 | I39: Hybrid | J39: $250k–$1M | K39: N | L39: N | M39: Guidelines only | N39: Y | O39: 15 | P39: 10 | Q39: Low (1–3) | R39: 2 | S39: Asset generation | T39: 2 | U39: Commercial LLM | W39: Contributor | X39: Monthly+ | Y39: Guidelines | Z39: Event tracking | AA39: None | AB39: =VALUE(R39)*6 -> 0 | AC39: =IFERROR(VLOOKUP(K39,PointsMap!D2:E3,2,0),0) -> 0 | AD39: =IFERROR(VLOOKUP(M39,PointsMap!G2:H5,2,0),0) -> 0 | AE39: =IFERROR(VLOOKUP(AA39,PointsMap!M2:N5,2,0),0) -> 0 | AF39: =IFERROR(VLOOKUP(Z39,PointsMap!J2:K5,2,0),0) -> 0 | AG39: =MIN(8,VALUE(T39)*2) -> 0 | AH39: =IFERROR(VLOOKUP(Q39,PointsMap!P2:Q5,2,0),0) -> 0 | AI39: =MIN(8,ROUND(VALUE(G39)*8,0)) -> 0 | AJ39: =IFERROR(VLOOKUP(I39,PointsMap!A2:B5,2,0),0) -> 0 | AK39: =IFERROR(VLOOKUP(W39,PointsMap!S2:T4,2,0),0) -> 0 | AL39: =IFERROR(VLOOKUP(X39,PointsMap!V2:W4,2,0),0) -> 0 | AM39: =MIN(5,VALUE(V39)) -> 0 | AN39: =AB39 -> 0 | AO39: =AC39+AD39+AE39+AF39 -> 0 | AP39: =AG39+AH39 -> 0 | AQ39: =AI39+AJ39 -> 0 | AR39: =AK39+AL39+AM39 -> 0 | AS39: =AN39*Weights!B3/100+AO39*Weights!B4/100+AP39*Weights!B5/100+AQ39*Weights!B6/100+AR39*Weights!B7/100 -> 0 | AT39: https://www.codeandtheory.com/expertise/technology | AY39: https://www.codeandtheory.com/careers | BB39: https://www.codeandtheory.com/thinking | BD39: Tech expertise; thinking hub.
